<?xml version="1.0" ?>
<!-- =================================================================================== -->
<!-- |    This document was autogenerated by xacro from /home/salva/peacetolero_ws/install/peacetolero_description/share/peacetolero_description/urdf/peacetolero_alpha.config.xacro | -->
<!-- |    EDITING THIS FILE BY HAND IS NOT RECOMMENDED                                 | -->
<!-- =================================================================================== -->
<robot name="peacetolero_alpha_config">
  <!-- Base Link -->
  <link name="peacetolero/base_link">
    <visual>
      <origin rpy="3.1416 0 -1.5708" xyz="0 0 0"/>
      <!-- <origin rpy="0 1.5708 0" xyz="0 0 0" /> -->
      <geometry>
        <!-- <mesh filename="package://peacetolero_description/meshes/peacetolero.dae" scale="1 1 1"/> -->
        <mesh filename="package://peacetolero_description/meshes/peacetolero_wheels.dae" scale="1 1 1"/>
      </geometry>
      <material name="blue">
        <color rgba="0 0 1 1"/>
      </material>
    </visual>
    <collision>
      <!-- <origin rpy="0 0 1.5708" xyz="0 0 0" /> -->
      <origin rpy="3.1416 0.0 -1.5708" xyz="0 0 0"/>
      <geometry>
        <mesh filename="package://peacetolero_description/meshes/peacetolero_wheels.dae" scale="1 1 1"/>
      </geometry>
    </collision>
  </link>
  <link name="peacetolero/alpha_suport">
    <visual>
      <origin rpy="0 0 1.5708" xyz="0 0 0"/>
      <geometry>
        <mesh filename="package://peacetolero_description/meshes/soporte_alpha.dae" scale="1 1 1"/>
      </geometry>
      <material name="blue">
        <color rgba="0 0 1 1"/>
      </material>
    </visual>
    <collision>
      <origin rpy="0 0 1.5708" xyz="0 0 0"/>
      <geometry>
        <mesh filename="package://peacetolero_description/meshes/soporte_alpha.dae" scale="1 1 1"/>
      </geometry>
    </collision>
  </link>
  <joint name="base_link2arm" type="fixed">
    <parent link="peacetolero/base_link"/>
    <child link="peacetolero/alpha_suport"/>
    <origin rpy="3.1416 0 0" xyz="0.0 0.0 0.0"/>
  </joint>
  <link name="peacetolero/zed_camera_link">
    </link>
  <link name="peacetolero/zed_camera_link1">
    </link>
  <!-- Define the fixed joint between base_link and zed_camera_link -->
  <joint name="base_to_zed" type="fixed">
    <parent link="peacetolero/base_link"/>
    <child link="peacetolero/zed_camera_link"/>
    <origin rpy="1.57 3.1416 1.57" xyz="0.2 0.0 0.0"/>
    <!-- Position and orientation of ZED relative to base_link -->
  </joint>
  <!-- Define the fixed joint between base_link and zed_camera_link -->
  <joint name="base_to_zed1" type="fixed">
    <parent link="peacetolero/base_link"/>
    <child link="peacetolero/zed_camera_link1"/>
    <origin rpy="1.57 3.1416 1.57" xyz="0.2 0.0 0.0"/>
    <!-- Position and orientation of ZED relative to base_link -->
  </joint>
  <material name="peacetolero/alpha_black">
    <color rgba="0.3 0.3 0.3 1"/>
  </material>
  <link name="peacetolero/alpha_base_link">
    <visual>
      <origin rpy="0 0 0" xyz="0 0 0"/>
      <geometry>
        <box size="0.001 0.001 0.001"/>
      </geometry>
    </visual>
    <inertial>
      <mass value="0.0001"/>
      <inertia ixx="0.0001" ixy="0" ixz="0" iyy="0.0001" iyz="0" izz="0.0001"/>
    </inertial>
  </link>
  <link name="peacetolero/alpha_m3_inline_link">
    <visual>
      <geometry>
        <mesh filename="file:///home/salva/ros2_ws/install/alpha_description/share/alpha_description/meshes/M3-INLINE.stl"/>
      </geometry>
      <origin rpy="0 0 0" xyz="0 0 0"/>
      <material name="peacetolero/alpha_black"/>
    </visual>
    <collision>
      <geometry>
        <cylinder length="0.150" radius="0.020"/>
      </geometry>
      <origin rpy="0 1.57075 0" xyz="-0.055 0 0"/>
    </collision>
    <inertial>
      <mass value="0.341"/>
      <origin xyz="-0.055 0 0"/>
      <inertia ixx="0.0000682" ixy="0" ixz="0" iyy="0.000673" iyz="0" izz="0.000673"/>
    </inertial>
  </link>
  <link name="peacetolero/alpha_m2_1_1_link">
    <visual>
      <geometry>
        <mesh filename="file:///home/salva/ros2_ws/install/alpha_description/share/alpha_description/meshes/M2-1-1.stl"/>
      </geometry>
      <origin rpy="0 0 0" xyz="0 0 0"/>
      <material name="peacetolero/alpha_black"/>
    </visual>
    <collision>
      <geometry>
        <cylinder length="0.033" radius="0.020"/>
      </geometry>
      <origin rpy="0 0 0" xyz="0 0 0.0165"/>
    </collision>
    <inertial>
      <mass value="0.194"/>
      <origin xyz="0 0 0.0165"/>
      <inertia ixx="0.000037" ixy="0" ixz="0" iyy="0.000037" iyz="0" izz="0.0000388"/>
    </inertial>
  </link>
  <link name="peacetolero/alpha_m2_joint_link">
    <visual>
      <geometry>
        <mesh filename="file:///home/salva/ros2_ws/install/alpha_description/share/alpha_description/meshes/M2.stl"/>
      </geometry>
      <origin rpy="0 0 0" xyz="0 0 0"/>
      <material name="peacetolero/alpha_black"/>
    </visual>
    <collision>
      <geometry>
        <cylinder length="0.145" radius="0.020"/>
      </geometry>
      <origin rpy="0 0 0" xyz="-0.02 0 -0.0725"/>
    </collision>
    <collision>
      <geometry>
        <cylinder length="0.040" radius="0.020"/>
      </geometry>
      <origin rpy="1.5707 0 0" xyz="0 0 0"/>
    </collision>
    <collision>
      <geometry>
        <cylinder length="0.040" radius="0.020"/>
      </geometry>
      <origin rpy="1.5707 0 0" xyz="-0.040 0 -0.1453"/>
    </collision>
    <inertial>
      <mass value="0.429"/>
      <origin xyz="-0.02 0 -0.0725"/>
      <inertia ixx="0.0008907" ixy="0" ixz="0" iyy="0.0008907" iyz="0" izz="0.0000858"/>
    </inertial>
  </link>
  <link name="peacetolero/alpha_m2_1_2_link">
    <visual>
      <geometry>
        <mesh filename="file:///home/salva/ros2_ws/install/alpha_description/share/alpha_description/meshes/M2-1-3.stl"/>
      </geometry>
      <origin rpy="0 0 0" xyz="0 0 0"/>
      <material name="peacetolero/alpha_black"/>
    </visual>
    <collision>
      <geometry>
        <cylinder length="0.033" radius="0.020"/>
      </geometry>
      <origin rpy="0 0 0" xyz="0.02 0 0.0165"/>
    </collision>
    <inertial>
      <mass value="0.115"/>
      <origin xyz="0.02 0 0.0165"/>
      <inertia ixx="0.0000219" ixy="0" ixz="0" iyy="0.0000219" iyz="0" izz="0.000023"/>
    </inertial>
  </link>
  <link name="peacetolero/alpha_m1_link">
    <visual>
      <geometry>
        <mesh filename="file:///home/salva/ros2_ws/install/alpha_description/share/alpha_description/meshes/RS1-100-101-123.stl"/>
      </geometry>
      <origin rpy="0 -1.5707 0" xyz="0 0 0"/>
      <material name="peacetolero/alpha_black"/>
    </visual>
    <collision>
      <geometry>
        <cylinder length="0.1" radius="0.020"/>
      </geometry>
      <origin rpy="0 0 0" xyz="0 0 0.05"/>
    </collision>
    <inertial>
      <mass value="0.200"/>
      <origin xyz="0 0 0.05"/>
      <inertia ixx="0.0001867" ixy="0" ixz="0" iyy="0.0001867" iyz="0" izz="0.00004"/>
    </inertial>
  </link>
  <link name="peacetolero/alpha_ee_base_link">
    <visual>
      <origin rpy="0 0 0" xyz="0 0 0"/>
      <geometry>
        <box size="0.001 0.001 0.001"/>
      </geometry>
    </visual>
    <inertial>
      <mass value="0.0001"/>
      <inertia ixx="0.0001" ixy="0" ixz="0" iyy="0.0001" iyz="0" izz="0.0001"/>
    </inertial>
  </link>
  <link name="peacetolero/alpha_push_rod">
    <visual>
      <origin rpy="0 0 0" xyz="0 0 0"/>
      <geometry>
        <box size="0.001 0.001 0.001"/>
      </geometry>
    </visual>
    <inertial>
      <mass value="0.0001"/>
      <inertia ixx="0.0001" ixy="0" ixz="0" iyy="0.0001" iyz="0" izz="0.0001"/>
    </inertial>
  </link>
  <joint name="peacetolero/alpha_base_joint" type="fixed">
    <origin rpy="3.1416 0 0" xyz="0.404 -0.03 0.048"/>
    <parent link="peacetolero/base_link"/>
    <child link="peacetolero/alpha_base_link"/>
  </joint>
  <joint name="peacetolero/alpha_base_link_joint" type="fixed">
    <parent link="peacetolero/alpha_base_link"/>
    <child link="peacetolero/alpha_m3_inline_link"/>
    <origin rpy="0 0 0"/>
  </joint>
  <joint name="peacetolero/alpha_axis_e" type="revolute">
    <parent link="peacetolero/alpha_m3_inline_link"/>
    <child link="peacetolero/alpha_m2_1_1_link"/>
    <origin xyz="0 0 0.014"/>
    <axis xyz="0 0 1"/>
    <limit effort="9.0" lower="0.0" upper="6.10" velocity="0.5"/>
  </joint>
  <joint name="peacetolero/alpha_axis_d" type="revolute">
    <parent link="peacetolero/alpha_m2_1_1_link"/>
    <child link="peacetolero/alpha_m2_joint_link"/>
    <origin xyz="-0.02 0 0.033"/>
    <axis xyz="0 1 0"/>
    <!-- The true lower limit is 0.0; however, this breaks for some reason with ros2_control -->
    <limit effort="9.0" lower="-3.49" upper="3.49" velocity="0.5"/>
  </joint>
  <joint name="peacetolero/alpha_axis_c" type="revolute">
    <parent link="peacetolero/alpha_m2_joint_link"/>
    <child link="peacetolero/alpha_m2_1_2_link"/>
    <origin rpy="0 0 3.14159" xyz="-0.04 0 -0.1453"/>
    <axis xyz="0 1 0"/>
    <limit effort="9.0" lower="0.0" upper="3.22" velocity="0.5"/>
  </joint>
  <joint name="peacetolero/alpha_axis_b" type="revolute">
    <parent link="peacetolero/alpha_m2_1_2_link"/>
    <child link="peacetolero/alpha_m1_link"/>
    <origin rpy="0 0 2.09439" xyz="0.02 0 0.033"/>
    <axis xyz="0 0 -1"/>
    <limit effort="9.0" lower="0.0" upper="3.22" velocity="0.5"/>
  </joint>
  <joint name="peacetolero/alpha_ee_joint" type="fixed">
    <origin rpy="0 0 0" xyz="0 0 0.09975"/>
    <parent link="peacetolero/alpha_m1_link"/>
    <child link="peacetolero/alpha_ee_base_link"/>
  </joint>
  <joint name="peacetolero/alpha_axis_a" type="fixed">
    <origin rpy="0 0 0" xyz="0 0 0.009"/>
    <parent link="peacetolero/alpha_ee_base_link"/>
    <child link="peacetolero/alpha_push_rod"/>
    <axis xyz="0 0 1"/>
    <limit effort="10" lower="0" upper="0.015" velocity="10"/>
  </joint>
  <material name="peacetolero/alpha_standard_jaws_black">
    <color rgba="0.3 0.3 0.3 1"/>
  </material>
  <link name="peacetolero/alpha_standard_jaws_base_link">
    <visual>
      <geometry>
        <mesh filename="file:///home/salva/ros2_ws/install/alpha_description/share/alpha_description/meshes/end_effectors/RS1-124.stl"/>
      </geometry>
      <material name="peacetolero/alpha_standard_jaws_black"/>
    </visual>
    <collision>
      <geometry>
        <cylinder length="0.00975" radius="0.020"/>
      </geometry>
      <origin rpy="0 0 0" xyz="0 0 0.004875"/>
    </collision>
    <inertial>
      <mass value="0.023"/>
      <origin xyz="0 0 0.004875"/>
      <inertia ixx="0.000002422" ixy="0" ixz="0" iyy="0.000002422" iyz="0" izz="0.0000046"/>
    </inertial>
  </link>
  <link name="peacetolero/alpha_standard_jaws_rs1_130_link">
    <visual>
      <geometry>
        <mesh filename="file:///home/salva/ros2_ws/install/alpha_description/share/alpha_description/meshes/end_effectors/RS1-130.stl"/>
      </geometry>
      <material name="peacetolero/alpha_standard_jaws_black"/>
      <origin rpy="0 0 0" xyz="0 0 0"/>
    </visual>
    <collision>
      <geometry>
        <box size="0.012 0.03 0.09"/>
      </geometry>
      <origin rpy="0 0 0" xyz="0.0 -0.008 0.045"/>
    </collision>
    <inertial>
      <mass value="0.055"/>
      <origin rpy="0 0 0" xyz="0.0 -0.008 0.045"/>
      <inertia ixx="0.00004125" ixy="0" ixz="0" iyy="0.000037785" iyz="0" izz="0.000004785"/>
    </inertial>
  </link>
  <link name="peacetolero/alpha_standard_jaws_rs1_139_link">
    <visual>
      <geometry>
        <mesh filename="file:///home/salva/ros2_ws/install/alpha_description/share/alpha_description/meshes/end_effectors/RS1-139.stl"/>
      </geometry>
      <material name="peacetolero/alpha_standard_jaws_black"/>
      <origin rpy="0 0 0" xyz="0 0 0"/>
    </visual>
    <collision>
      <geometry>
        <box size="0.012 0.03 0.09"/>
      </geometry>
      <origin rpy="0 0 0" xyz="0.0 0.008 0.045"/>
    </collision>
    <inertial>
      <mass value="0.055"/>
      <origin rpy="0 0 0" xyz="0.0 0.008 0.045"/>
      <inertia ixx="0.00004125" ixy="0" ixz="0" iyy="0.000037785" iyz="0" izz="0.000004785"/>
    </inertial>
  </link>
  <link name="peacetolero/alpha_standard_jaws_tool">
    <inertial>
      <mass value="0.0001"/>
      <inertia ixx="0.0001" ixy="0" ixz="0" iyy="0.0001" iyz="0" izz="0.0001"/>
    </inertial>
  </link>
  <joint name="peacetolero/alpha_standard_jaws_base_joint" type="fixed">
    <origin rpy="0 0 0" xyz="0 0 0"/>
    <parent link="peacetolero/alpha_ee_base_link"/>
    <child link="peacetolero/alpha_standard_jaws_base_link"/>
    <origin rpy="0 0 0" xyz="0 0 0"/>
  </joint>
  <joint name="peacetolero/alpha_standard_jaws_rs1_130_joint" type="fixed">
    <origin rpy="0 0 0" xyz="0 0.0155 0.0069"/>
    <parent link="peacetolero/alpha_standard_jaws_base_link"/>
    <child link="peacetolero/alpha_standard_jaws_rs1_130_link"/>
    <axis xyz="-1 0 0"/>
    <limit effort="10" lower="0" upper="0.5" velocity="10"/>
    <mimic joint="peacetolero/alpha_axis_a" multiplier="51" offset="0"/>
  </joint>
  <joint name="peacetolero/alpha_standard_jaws_rs1_139_joint" type="fixed">
    <origin rpy="0 0 0" xyz="0 -0.0155 0.0069"/>
    <parent link="peacetolero/alpha_standard_jaws_base_link"/>
    <child link="peacetolero/alpha_standard_jaws_rs1_139_link"/>
    <axis xyz="1 0 0"/>
    <limit effort="10" lower="0" upper="0.5" velocity="10"/>
    <mimic joint="peacetolero/alpha_standard_jaws_rs1_130_joint" multiplier="1" offset="0"/>
  </joint>
  <joint name="peacetolero/alpha_standard_jaws_tool_joint" type="fixed">
    <origin rpy="0 -1.571 0" xyz="0 0 0.04"/>
    <parent link="peacetolero/alpha_standard_jaws_base_link"/>
    <child link="peacetolero/alpha_standard_jaws_tool"/>
  </joint>
  <ros2_control name="ReachAlpha5" type="system">
    <hardware>
      <plugin>alpha_hardware/alpha_stonefish_hardware</plugin>
    </hardware>
    <joint name="peacetolero/alpha_axis_a">
      <command_interface name="position">
        <param name="min">0</param>
        <param name="max">0.015</param>
      </command_interface>
      <command_interface name="velocity">
        <param name="min">-2.5</param>
        <param name="max">2.5</param>
      </command_interface>
      <state_interface name="position">
        <param name="initial_value">0</param>
      </state_interface>
      <state_interface name="velocity">
        <param name="initial_value">0.0</param>
      </state_interface>
    </joint>
    <joint name="peacetolero/alpha_axis_b">
      <command_interface name="position">
        <param name="min">0</param>
        <param name="max">3.22</param>
      </command_interface>
      <command_interface name="velocity">
        <param name="min">-1.0</param>
        <param name="max">1.0</param>
      </command_interface>
      <state_interface name="position">
        <param name="initial_value">0</param>
      </state_interface>
      <state_interface name="velocity">
        <param name="initial_value">0.0</param>
      </state_interface>
    </joint>
    <joint name="peacetolero/alpha_axis_c">
      <command_interface name="position">
        <param name="min">0</param>
        <param name="max">3.22</param>
      </command_interface>
      <command_interface name="velocity">
        <param name="min">-1.0</param>
        <param name="max">1.0</param>
      </command_interface>
      <state_interface name="position">
        <param name="initial_value">0</param>
      </state_interface>
      <state_interface name="velocity">
        <param name="initial_value">0.0</param>
      </state_interface>
    </joint>
    <joint name="peacetolero/alpha_axis_d">
      <command_interface name="position">
        <param name="min">0</param>
        <param name="max">3.49</param>
      </command_interface>
      <command_interface name="velocity">
        <param name="min">-1.0</param>
        <param name="max">1.0</param>
      </command_interface>
      <state_interface name="position">
        <param name="initial_value">1.5746</param>
      </state_interface>
      <state_interface name="velocity">
        <param name="initial_value">0.0</param>
      </state_interface>
    </joint>
    <joint name="peacetolero/alpha_axis_e">
      <command_interface name="position">
        <param name="min">0</param>
        <param name="max">6.10</param>
      </command_interface>
      <command_interface name="velocity">
        <param name="min">-0.5</param>
        <param name="max">0.5</param>
      </command_interface>
      <state_interface name="position">
        <param name="initial_value">0</param>
      </state_interface>
      <state_interface name="velocity">
        <param name="initial_value">0.0</param>
      </state_interface>
    </joint>
  </ros2_control>
</robot>
